Workbook

Sheet 0. README
A1: SkinBB HLHP — Scenario Library v3.4 (Evidence-Base enrichment) -> adds 4 evidence-backed concerns (Premature Aging/Sun Damage, Fungal, Heat Rash, Dark Marks/PIH), Nutrition & Lifestyle modifier layers, and a Did-You-Know education layer. Built on v3.3.1 (SFI recalibration). Architecture, schema and tone unchanged. -> v3.6 adds sheet 17 (Routine Change Rules) for the 'What's Different Today' card
A3: What this is
A4: A synthesis layer between the published evidence (1,800+ PubMed-cited findings) and the HLHP/SFI
A5: user-facing engine. Every cell maps a specific environmental scenario × skin type × concern to:
A6: • Risk score (0–5)
A7: • Confidence tier (HIGH / MODERATE / INFERRED) with cite count
A8: • Three alert levels (L0 compact / L1 personalised / L2 explainer) — all product-free
A9: • PMID anchors for traceability
A10: • Indian climatic zone applicability
A12: How it works
A13: 1. SINGLE-FACTOR cells (750): Factor × Band × Skin Type × Concern.
A14: For each cell, the system queries the evidence base for rows whose trigger band and user filter
... A128: 'Time Overlay' sheet's why-it-matters column + a real citation, and get dermatologist sign-off before shipping.

Sheet System Map
A1: SYSTEM MAP — SkinBB HLHP Scenario Library
A2: Read-only overview of every sheet, its role, and how the scenario counts multiply out. Nothing here changes the model — it's a mirror to think from.
A3: ="Generated "&TEXT(TODAY(),"dd-mmm-yyyy")&" · "&COUNTA(A6:A39)&" sheets inventoried below"
A5: # | B5: Sheet | C5: Category | D5: Lang | E5: Purpose | F5: Rows | G5: Flag
A6: 1 | B6: 0. README | C6: Meta / Docs | D6: EN | E6: Master changelog, architecture, locked principles, sheet map | F6: =COUNTA('0. README'!A:A)
A7: 2 | B7: 1. India Climatic Zones | C7: Reference | D7: EN | E7: 6 zones, 62 cities, seasonal band profiles | F7: =COUNTA('1. India Climatic Zones'!A:A)
A8: 3 | B8: 2. Bands Reference | C8: Reference | D8: EN | E8: Locked band thresholds (mirrors live engine) | F8: =COUNTA('2. Bands Reference'!A:A)
A9: 4 | B9: 3. Confidence Framework | C9: Reference | D9: EN | E9: HIGH / MODERATE / INFERRED rules + evidence audit | F9: =COUNTA('3. Confidence Framework'!A:A)
A10: 5 | B10: Time-of-Day Logic | C10: Reference | D10: EN | E10: Time-of-day modifier logic | F10: =COUNTA('Time-of-Day Logic'!A:A)
A11: 6 | B11: Time Overlay | C11: Reference | D11: EN | E11: Time overlay matrix | F11: =COUNTA('Time Overlay'!A:A)
A12: 7 | B12: Gap Analysis | C12: Reference / Meta | D12: EN | E12: Coverage gaps & conflicts (the roadmap) | F12: =COUNTA('Gap Analysis'!A:A)
A13: 8 | B13: 4. Temperature Cells | C13: Production · Single-factor | D13: EN | E13: Temperature × band × skin type × concern | F13: =COUNTA('4. Temperature Cells'!A:A)
A14: 9 | B14: 5. AQI Cells | C14: Production · Single-factor | D14: EN | E14: AQI × band × skin type × concern | F14: =COUNTA('5. AQI Cells'!A:A)
A15: 10 | B15: 6. UV Cells | C15: Production · Single-factor | D15: EN | E15: UV × band × skin type × concern | F15: =COUNTA('6. UV Cells'!A:A)
A16: 11 | B16: 7. Humidity Cells | C16: Production · Single-factor | D16: EN | E16: Humidity × band × skin type × concern | F16: =COUNTA('7. Humidity Cells'!A:A)
A17: 12 | B17: 8. Compound Scenarios Index | C17: Production · Compound | D17: EN | E17: 21 named India scenarios (C01–C21) w/ bands, zones, seasons | F17: =COUNTA('8. Compound Scenarios Index'!A:A)
A18: 13 | B18: 9. Compound Cell Library | C18: Production · Compound | D18: EN | E18: Compound cells: scenario × skin × concern, L0/L1/L2 | F18: =COUNTA('9. Compound Cell Library'!A:A)
A19: 14 | B19: 10. Master Library | C19: Production · Master | D19: EN | E19: All single-factor cells, flat-queryable (union of 4–7) | F19: =COUNTA('10. Master Library'!A:A)
A20: 15 | B20: 11. Guest Mode | C20: Production · Guest | D20: EN | E20: Guest-mode variant (no personalisation) | F20: =COUNTA('11. Guest Mode'!A:A)
A21: 16 | B21: 12. Age Modifiers | C21: Modifier layer | D21: EN | E21: Age-based nudges | F21: =COUNTA('12. Age Modifiers'!A:A)
A22: 17 | B22: 13. Gender + Life-Stage | C22: Modifier layer | D22: EN | E22: Gender & life-stage nudges | F22: =COUNTA('13. Gender + Life-Stage'!A:A)
A23: 18 | B23: 14. Nutrition Modifiers | C23: Modifier layer | D23: EN | E23: 7 evidence-backed nutrition nudges | F23: =COUNTA('14. Nutrition Modifiers'!A:A)
A24: 19 | B24: 15. Lifestyle Modifiers | C24: Modifier layer | D24: EN | E24: 7 lifestyle nudges | F24: =COUNTA('15. Lifestyle Modifiers'!A:A)
A25: 20 | B25: 16. Did-You-Know Nuggets | C25: Education layer | D25: EN | E25: Cited education micro-cards | F25: =COUNTA('16. Did-You-Know Nuggets'!A:A)
A26: 21 | B26: 17. Routine Change Rules | C26: Modifier layer | D26: EN | E26: What's Different Today' card logic | F26: =COUNTA('17. Routine Change Rules'!A:A)
A27: 22 | B27: Glossary | C27: Meta / Docs | D27: EN | E27: Term definitions | F27: =COUNTA(Glossary!A:A)
A28: 23 | B28: Hindi (Devanagari) | C28: Translation | D28: HI | E28: Master Hindi string table | F28: =COUNTA('Hindi (Devanagari)'!A:A)
A29: 24 | B29: Guest Mode Hindi | C29: Translation | D29: HI | E29: Mirror of 11. Guest Mode | F29: =COUNTA('Guest Mode Hindi'!A:A)
A30: 25 | B30: Time Overlay Hindi | C30: Translation | D30: HI | E30: Mirror of Time Overlay | F30: =COUNTA('Time Overlay Hindi'!A:A)
A31: 26 | B31: Did-You-Know Nuggets Hindi | C31: Translation | D31: HI | E31: Mirror of 16. Nuggets | F31: =COUNTA('Did-You-Know Nuggets Hindi'!A:A)
A32: 27 | B32: Temperature Cells Hindi | C32: Translation | D32: HI | E32: Mirror of 4. Temperature Cells | F32: =COUNTA('Temperature Cells Hindi'!A:A)
A33: 28 | B33: AQI Cells Hindi | C33: Translation | D33: HI | E33: Mirror of 5. AQI Cells | F33: =COUNTA('AQI Cells Hindi'!A:A)
A34: 29 | B34: UV Cells Hindi | C34: Translation | D34: HI | E34: Mirror of 6. UV Cells | F34: =COUNTA('UV Cells Hindi'!A:A)
A35: 30 | B35: Humidity Cells Hindi | C35: Translation | D35: HI | E35: Mirror of 7. Humidity Cells | F35: =COUNTA('Humidity Cells Hindi'!A:A)
A36: 31 | B36: Compound Cell Library Hindi | C36: Translation | D36: HI | E36: Mirror of 9. Compound Cell Library | F36: =COUNTA('Compound Cell Library Hindi'!A:A)
A37: 32 | B37: Master Library Hindi | C37: Translation | D37: HI | E37: Mirror of 10. Master Library | F37: =COUNTA('Master Library Hindi'!A:A)
A38: 33 | B38: 6. UV Cells (backup v3.6) | C38: ⚠ BACKUP | D38: EN | E38: Stray backup living in production file | F38: =COUNTA('6. UV Cells (backup v3.6)'!A:A) | G38: Move out / delete
A39: 34 | B39: Temp Cells backup v3.6 | C39: ⚠ BACKUP | D39: EN | E39: Stray backup living in production file | F39: =COUNTA('Temp Cells backup v3.6'!A:A) | G39: Move out / delete
A42: THE COMBINATORICS — where the scenario count comes from
A44: Dimension | B44: Count | C44: Values
...

Sheet 1. India Climatic Zones
A1: Zone Code | B1: Zone Name | C1: Description | D1: Dominant Skin Stressors | E1: Cities (sample) | F1: # Cities
A2: HD | B2: Hot & Dry | C2: NW deserts and adjoining plains. Extreme summer heat, severe winter dryness, low humidity year-round, occasional dust storms. | D2: Critical low humidity · Extreme heat · Very high UV · Dust irritation | E2: Jodhpur, Bikaner, Jaisalmer, Jaipur, Ahmedabad, Bhuj ... | F2: 10
A3: HH | B3: Warm & Humid Coastal | C3: All Indian coastlines (Arabian Sea and Bay of Bengal). High humidity year-round, moderate temperature range, salt air, intense monsoon. | D3: Very high humidity · Sweat-sebum pore-clogging · Heat + humidity combination · Reflected UV at beaches | E3: Mumbai, Chennai, Kolkata, Goa, Mangalore, Kochi ... | F3: 29
A4: CN | B4: Composite North Plains | C4: Indo-Gangetic Plain. Extreme summer, cold dry winters, monsoon rains, severe AQI in winter from inversion + stubble burning. | D4: Severe winter AQI (inversion + stubble) · Cold + dry winter combination · Extreme summer heat · Pre-monsoon dust | E4: Delhi, Gurgaon, Noida, Faridabad, Lucknow, Kanpur ... | F4: 22
A5: TP | B5: Temperate Plateau | C5: Deccan Plateau. Mild year-round temperatures, predictable monsoon, moderate humidity, generally optimal for skin. | D5: Pre-monsoon UV spike · Mild humidity swings · Localized city AQI (Bengaluru, Hyderabad) | E5: Bengaluru, Pune, Hyderabad, Mysore, Nashik, Coimbatore ... | F5: 14
A6: CH | B6: Cold Himalayan | C6: Himalayan belt — high altitude. Cold winters, mild summers, intense UV at altitude, snow reflection, low humidity in winter. | D6: Altitude UV intensification (+10–12% per 1000m) · Snow-reflected UV (up to 80%) · Extreme cold + dry winter · Wind chill barrier compromise | E6: Shimla, Manali, Srinagar, Leh, Darjeeling, Gangtok ... | F6: 13
A7: TN | B7: Tropical Northeast | C7: Northeast India — high rainfall, very high humidity year-round, mild temperature range, moderate UV with frequent cloud cover. | D7: Year-round high humidity (fungal risk) · Heavy monsoon saturation · Sweat-trapping in folds | E7: Guwahati, Shillong, Imphal, Agartala, Aizawl, Itanagar ... | F7: 9
A10: Zone × Season Typical Band Profile
A11: Zone | B11: Season | C11: Temperature | D11: Humidity | E11: UV | F11: AQI
A12: HD | B12: Summer (Apr–Jun) | C12: Hot to Extreme Heat | D12: Critical Low to Low | E12: Very High to Extreme | F12: 10
A13: HD | B13: Monsoon (Jul–Sep) | C13: Warm to Hot | D13: Low to High | E13: High | F13: 10
A14: HD | B14: Winter (Dec–Jan) | C14: Cool to Cold | D14: Very Low to Low | E14: Moderate | F14: 10
A15: HD | B15: Post-monsoon (Oct–Nov) | C15: Warm | D15: Low | E15: High | F15: 10
A16: HH | B16: Summer (Mar–May) | C16: Warm to Hot | D16: High to Very High | E16: Very High | F16: 29
A17: HH | B17: Monsoon (Jun–Sep) | C17: Warm | D17: Very High to Extreme | E17: Moderate (cloudy) | F17: 29
A18: HH | B18: Post-monsoon (Oct–Nov) | C18: Warm | D18: High | E18: High | F18: 29
A19: HH | B19: Winter (Dec–Feb) | C19: Cool to Warm | D19: High | E19: Moderate | F19: 29
A20: CN | B20: Summer (Apr–Jun) | C20: Hot to Extreme Heat | D20: Low | E20: Very High | F20: 22
A21: CN | B21: Monsoon (Jul–Sep) | C21: Warm to Hot | D21: High to Very High | E21: High | F21: 22
A22: CN | B22: Post-monsoon (Oct–Nov) | C22: Warm to Cool | D22: Low to Moderate | E22: Moderate to High | F22: 22
A23: CN | B23: Winter (Dec–Feb) | C23: Cold to Cool | D23: Very Low to Low | E23: Moderate | F23: 22
... A34: TN | B34: Winter (Dec–Feb) | C34: Cool to Warm | D34: High | E34: Moderate | F34: 9
A37: City → Zone Lookup
A38: City | B38: Zone Code | C38: Zone Name
A39: Agartala | B39: TN | C39: Tropical Northeast
A40: Agra | B40: CN | C40: Composite North Plains
A41: Ahilyanagar | B41: TP | C41: Temperate Plateau
A42: Ahmedabad | B42: HD | C42: Hot & Dry
A43: Aizawl | B43: TN | C43: Tropical Northeast
A44: Ajmer | B44: HD | C44: Hot & Dry
A45: Allahabad | B45: CN | C45: Composite North Plains
A46: Amritsar | B46: CN | C46: Composite North Plains
A47: Bengaluru | B47: TP | C47: Temperate Plateau
A48: Bhopal | B48: CN | C48: Composite North Plains
A49: Bhubaneswar | B49: HH | C49: Warm & Humid Coastal
... A135: Visakhapatnam | B135: HH | C135: Warm & Humid Coastal

Sheet 2. Bands Reference
A1: Factor | B1: Band Label | C1: Range | D1: Points (of 25) | E1: Band Key
A2: Temperature
B3: Extreme Cold | C3: <5°C | D3: 0 | E3: extreme_cold
B4: Cold | C4: 5–14°C | D4: 5 | E4: cold
B5: Cool | C5: 15–19°C | D5: 12 | E5: cool
B6: Optimal | C6: 20–27°C | D6: 25 | E6: optimal
B7: Warm | C7: 28–34°C | D7: 12 | E7: warm
B8: Hot | C8: 35–42°C | D8: 5 | E8: hot
B9: Extreme Heat | C9: >42°C | D9: 0 | E9: extreme_heat
A10: AQI
B11: Good | C11: 0–50 | D11: 25 | E11: good
B12: Satisfactory | C12: 51–100 | D12: 18 | E12: satisfactory
B13: Moderate | C13: 101–200 | D13: 10 | E13: moderate
B14: Poor | C14: 201–300 | D14: 5 | E14: poor
B15: Very Poor | C15: 301–400 | D15: 2 | E15: very_poor
B16: Severe | C16: >400 | D16: 0 | E16: severe
A17: UV
B18: Low | C18: 0–2 | D18: 25 | E18: low
B19: Moderate | C19: 3–5 | D19: 18 | E19: moderate
B20: High | C20: 6–7 | D20: 11 | E20: high
B21: Very High | C21: 8–10 | D21: 5 | E21: very_high
B22: Extreme | C22: 11+ | D22: 0 | E22: extreme
A23: Humidity
B24: Critical Low | C24: <10% | D24: 0 | E24: critical_low
B25: Very Low | C25: 10–19% | D25: 5 | E25: very_low
B26: Low | C26: 20–39% | D26: 12 | E26: low
B27: Optimal | C27: 40–60% | D27: 25 | E27: optimal
B28: High | C28: 61–79% | D28: 15 | E28: high
B29: Very High | C29: 80–89% | D29: 9 | E29: very_high
B30: Extreme | C30: >90% | D30: 5 | E30: extreme

Sheet 3. Confidence Framework
A1: Tier | B1: Criteria | C1: Color | D1: Operational meaning | E1: 60% problem signal
A2: HIGH | B2: ≥2 PMID-cited findings AND ≥1 India/Fitzpatrick III–V relevant | C2: HIGH | D2: Engine can surface confidently; minimal editorial caveat needed. | E2: Not a gap.
A3: MODERATE | B3: ≥2 PMID-cited findings OR (≥1 PMID + ≥1 book citation) | C3: MODERATE | D3: Engine surfaces with standard caveat; flag for editorial review. | E3: Partial gap — India-specific research needed.
A4: INFERRED | B4: Mechanism-consistent extrapolation only (no direct PMID for the cell) | C4: INFERRED | D4: Engine surfaces with explicit hedge; treat as roadmap item. | E4: Direct 60% problem signal — research priority.

Sheet Time-of-Day Logic
A1: Time-of-Day Logic — engine specification (v3.5, 3-window model)
A2: PURPOSE: scenario cells describe CURRENT environmental bands (UV/AQI/temperature/humidity). They are time-blind — the same cell shows the same alert at 7am and 9pm. This sheet specifies how the engine reshapes the ACTION half of each alert by the user's LOCAL clock. The science (the condition-describing first sentence) does not change — only the action / framing does. No cells are pre-generated; this is an implementation spec.
A4: 1. The three time windows (user's local time)
A5: Window | B5: Local time | C5: Framing | D5: What the alert should do
A6: MORNING | B6: before ~09:00 | C6: CURRENT + ANTICIPATORY | D6: State what conditions are RIGHT NOW, then — only if a band change is forecast today — add the 'later it will…' note so the user can prep before going out.
A7: DAYTIME | B7: 09:00–16:00 | C7: CURRENT (peak / present-tense) | D7: Describe what is happening now and the protective action. This is exactly what the existing v3.5 cell text already does.
A8: EVENING→NIGHT | B8: after ~16:00 | C8: CURRENT → repair | D8: Describe current conditions (the peak is behind, so little left to anticipate today). As evening sets in, pivot the action from 'protect' to 'cleanse off the day + overnight repair'.
A10: WHY THREE, NOT FOUR: an earlier draft used a pure-anticipatory morning that hid the present ('UV climbs to extreme by midday') and an anticipatory evening. Both were wrong. Morning must be honest about NOW (a 7am walker needs to know UV is low right now) AND flag the coming peak. After ~4pm the day's peak has passed, so there is nothing left to anticipate — the alert is simply current conditions easing into the evening repair story. Anticipating at 6pm would mean forecasting tomorrow, which is a different feature.
A12: 2. When to add the anticipatory 'coming change' note — the band-change rule
A13: RULE: in the MORNING window, add the anticipatory note for ANY factor — UV, AQI, Temperature OR Humidity — IF AND ONLY IF today's forecast shows that factor crossing into a DIFFERENT BAND later today. The trigger is a forecast band change, not which factor it is. This is data-driven, not factor-stereotyped: if UV stays 'Low' all day, do NOT promise a peak; if Temperature jumps Warm→Extreme Heat by afternoon, DO warn — even though temperature is normally a 'current' factor.
A15: Factor | B15: Typical morning behaviour | C15: Anticipatory note fires when… | D15: Example morning line
A16: UV | B16: Almost always climbs from ~0 to a midday peak → usually crosses bands. | C16: Forecast peak band > current band (the common case). | D16: 'UV is low now but climbs to Very High by midday — sun protection on before you head out.'
A17: AQI | B17: Often worsens through the morning commute / evening inversion in cities. | C17: Forecast AQI band worsens later (e.g. Moderate→Poor). | D17: 'Air is moderate now but worsens through the commute — cleanse off grime when you get in.'
A18: Temperature | B18: Usually stable band; occasionally crosses on heatwave / cold-snap days. | C18: Forecast crosses a band (e.g. Warm→Extreme Heat, or Cool→Cold tonight). | D18: 'Pleasant now, but it climbs into a heatwave by afternoon — plan shade and water.'
A19: Humidity | B19: Usually stable; can cross around monsoon onset or a weather front. | C19: Forecast crosses a band (e.g. Optimal→Very High as rain sets in). | D19: 'Comfortable now, but it turns very humid later — keep skin and folds dry through the day.'
A21: If the factor's band is forecast to stay the SAME all day, the morning alert is just current-conditions (no anticipatory clause). If only the current value is available (no forecast), omit the anticipatory note entirely — never invent a peak.
A23: 3. Worked examples — same sensor reading, six open-times (3-window model)
A24: Example A — UV forecast to cross Low→Extreme today (band change → anticipatory note fires in the morning):
A25: Opens at | B25: UV now | C25: Window | D25: L0 the guest should see
A26: 7:00 am | B26: Low (~1) | C26: MORNING | D26: UV is low right now but climbs to extreme by midday. Easy outdoors now; sun protection on before you're out later.
A27: 9:00 am | B27: High (~6) | C27: MORNING→DAYTIME | D27: UV is strong now and still climbing. Cover up and use daily broad-spectrum sun protection.
A28: 12:00 noon | B28: Extreme (~11) | C28: DAYTIME | D28: UV is at danger levels — skin can burn in minutes. Limit midday sun; cover up and reapply often.
A29: 4:00 pm | B29: Moderate (~5) | C29: EVENING | D29: UV is easing but still real. Keep protection on if you're out — the worst is behind you.
A30: 6:00 pm | B30: Low (~1) | C30: EVENING→NIGHT | D30: The day's strong sun is over. Cleanse off sweat and sunscreen when you settle in.
A31: 9:00 pm | B31: 0 | C31: NIGHT | D31: Sun load for the day is done. Cleanse off the day, moisturise, and let skin repair overnight.
A33: Example B — Temperature forecast Warm→Extreme Heat (a 'current' factor that DOES get an anticipatory note because the band changes):
A34: Opens at | B34: Window | C34: L0 the guest should see
A35: 7:00 am | B35: MORNING | C35: Warm and comfortable now, but a heatwave builds by afternoon. Plan shade and water before it peaks.
A36: 12:00 noon | B36: DAYTIME | C36: Heatwave conditions now — your body and skin are dehydrating. Drink water, stay shaded, rinse off sweat.
A37: 6:00 pm | B37: EVENING→NIGHT | C37: The peak heat is easing. Rehydrate, rinse off the day's sweat, and keep skin lightly moisturised.
A38: 9:00 pm | B38: NIGHT | C38: Cooler now. A gentle cleanse and a light moisturiser before bed help skin recover from the hot day.
A40: Example C — Humidity Very High and forecast to STAY Very High all day (no band change → NO anticipatory note; current-conditions throughout):
A41: Opens at | B41: Window | C41: L0 the guest should see
A42: 7:00 am | B42: MORNING | C42: Very humid, sweaty air today. Keep skin and folds dry; use a light, water-based moisturiser.
A43: 12:00 noon | B43: DAYTIME | C43: Very humid — sweat and oil sit on skin. Cleanse off sweat and keep folds dry.
A44: 9:00 pm | B44: NIGHT | C44: Still humid tonight. A gentle cleanse before bed clears sweat and oil; keep moisturiser light.
A46: 4. How each window reshapes the three alert levels
A47: Level | B47: Morning (current + anticipatory) | C47: Daytime (current peak) | D47: Evening→Night (current → repair)
A48: L0 (≤20w) | B48: Current state + 'prep before you go out'; add coming-band note only if forecast to change. | C48: Current condition + present protective action. = existing cell. | D48: Current easing → 'cleanse off the day'; by night, repair line only (no 'protect/shield').
A49: L1 (≤40w) | B49: Current personalised action + anticipatory prep; keep 'if outdoor time today is long' frame. | C49: Current personalised action (existing cell). | D49: Protect-if-still-out early; by night: cleanse off the day, moisturise, note overnight repair.
...

Sheet Time Overlay
A1: Time Overlay — morning + evening/night action clauses (v3.5)
A2: HOW THE ENGINE USES THIS: MORNING (before ~09:00): if the forecast moves a factor into a WORSE band, append a morning add-on — rotate D and E; use F instead when the jump is 2+ bands; if the band IMPROVES into a better band, use the good-news note (G); otherwise show current conditions only. EARLY EVENING (~16:00–20:00): use column H (protection wording allowed until ~20:00). NIGHT (after ~20:00): rotate I / J / K — no daytime protection verbs (QA check in column N). Column L adds a rotating 'why it matters' insight (DYK refs → sheet 16). Column M records keying/context flags; column O tracks max words per row. All clauses are product-free (category words only), plain, and short.
A4: Single-factor overlays (by band)
A5: Type | B5: Factor / Scenario | C5: Band / Key | D5: Morning add-on (use only if the band worsens today) | E5: Morning add-on — variant B (rotate with D) | F5: Morning add-on — big-jump variant (band worsens 2+ steps) | G5: Morning good-news note (use only if the band improves today) | H5: Early-evening action (~4–8pm) | I5: Night action (after ~8pm) | J5: Night action — variant B (rotate with I) | K5: Night action — variant C (rotate with I) | L5: Why it matters (micro-insight; DYK ref where noted) | M5: Keying & context flags | N5: QA: banned night verbs | O5: QA: max words (D:K)
A6: UV | B6: UV | C6: Low | D6: — (UV low and staying low; no prep note needed) | G6: UV eases right down today — a lighter routine works; enjoy the gentler sun. | H6: UV is low and fading with the light — nothing extra needed if you're out. | I6: UV is done for the day — cleanse off the day and moisturise before bed. | J6: No sun to undo tonight — a simple cleanse and moisturiser will do. | K6: Quiet sun day — tonight is just cleanse, moisturise, sleep. | L6: Even darker-toned skin, which filters most UVB, still tans and spots — low UV just means less urgency. (DYK #1) | M6: Keyed to FORECAST band (add-on describes the band the day rises into) | N6: {=IF(SUMPRODUCT(--ISNUMBER(SEARCH({"cover up","seek shade","reapply","sun protection","protection on","protect "},I6&" "&J6&" "&K6)))>0,"⚠ banned night verb","OK")} | O6: {=MAX(IF(LEN(TRIM(D6:K6))=0,0,LEN(TRIM(D6:K6))-LEN(SUBSTITUTE(TRIM(D6:K6)," ",""))+1))}
A7: UV | B7: UV | C7: Moderate | D7: It climbs higher by midday — sun protection on before you head out. | E7: Heading out? The sun strengthens by midday — protection on first. | H7: UV is easing but still around — keep protection on if you're still out. | I7: Sun is down — cleanse off sunscreen and the day, then moisturise. | J7: Day's sun done — wash it off and give skin its overnight drink. | K7: Sun's off duty — your cleanse takes over from your sunscreen. | L7: At UV 8 skin reaches damage thresholds within minutes — moderate isn't harmless. (DYK #2) | M7: Keyed to FORECAST band | N7: {=IF(SUMPRODUCT(--ISNUMBER(SEARCH({"cover up","seek shade","reapply","sun protection","protection on","protect "},I7&" "&J7&" "&K7)))>0,"⚠ banned night verb","OK")} | O7: {=MAX(IF(LEN(TRIM(D7:K7))=0,0,LEN(TRIM(D7:K7))-LEN(SUBSTITUTE(TRIM(D7:K7)," ",""))+1))}
A8: UV | B8: UV | C8: High | D8: It turns strong by midday — cover up and put on sun protection before you're out. | E8: Midday sun turns harsh today — sort your sun protection before you leave. | F8: A two-band UV jump today — from gentle morning to harsh midday; protection before you leave. | H8: Sun is weakening but not done — keep protection on till sundown. | I8: The day's sun is over — cleanse off sunscreen and sweat, then moisturise. | J8: Sunscreen and sweat come off tonight — then moisturise and rest. | K8: Trade sunscreen for moisturiser tonight — skin repairs while you sleep. | L8: Sweat strips up to ~40% of your protection — the midday reapply is what keeps strong sun in check. (DYK #5) | M8: Keyed to FORECAST band | N8: {=IF(SUMPRODUCT(--ISNUMBER(SEARCH({"cover up","seek shade","reapply","sun protection","protection on","protect "},I8&" "&J8&" "&K8)))>0,"⚠ banned night verb","OK")} | O8: {=MAX(IF(LEN(TRIM(D8:K8))=0,0,LEN(TRIM(D8:K8))-LEN(SUBSTITUTE(TRIM(D8:K8)," ",""))+1))}
A9: UV | B9: UV | C9: Very High | D9: It peaks very high by midday — sun protection and shade planned before you go. | E9: Big sun today — pack shade plans and protection before stepping out. | F9: UV jumps several bands to very high today — full protection and shade before you're out. | H9: Still strong for a while yet — protection stays on if you're outdoors. | I9: Sun load is done — cleanse off the day well and let skin repair overnight. | J9: The sun took its toll today — cleanse gently and let repair begin. | K9: Skin worked hard in that sun — clean slate tonight, repair by morning. | L9: Shade, hat and cover-up each add real protection beyond any cream on a very-high day. (DYK #27) | M9: Keyed to FORECAST band | N9: {=IF(SUMPRODUCT(--ISNUMBER(SEARCH({"cover up","seek shade","reapply","sun protection","protection on","protect "},I9&" "&J9&" "&K9)))>0,"⚠ banned night verb","OK")} | O9: {=MAX(IF(LEN(TRIM(D9:K9))=0,0,LEN(TRIM(D9:K9))-LEN(SUBSTITUTE(TRIM(D9:K9)," ",""))+1))}
A10: UV | B10: UV | C10: Extreme | D10: It hits extreme by midday — limit midday sun and cover up before you head out. | E10: Today's sun peaks at extreme — plan around midday and cover up early. | F10: UV rockets to extreme from a mild start — plan the whole day around avoiding midday sun. | H10: Easing from extreme, but the sun still bites — protection and shade till sunset. | I10: No more sun today — cleanse off thoroughly and moisturise for overnight repair. | J10: Big-sun day over — a thorough cleanse tonight sets up overnight repair. | K10: Extreme-UV day behind you — tonight's cleanse and moisturiser do the repair work. | L10: Reapplying ~20 min after heading out cuts your sun dose more than waiting two hours. (DYK #24) | M10: Keyed to FORECAST band | N10: {=IF(SUMPRODUCT(--ISNUMBER(SEARCH({"cover up","seek shade","reapply","sun protection","protection on","protect "},I10&" "&J10&" "&K10)))>0,"⚠ banned night verb","OK")} | O10: {=MAX(IF(LEN(TRIM(D10:K10))=0,0,LEN(TRIM(D10:K10))-LEN(SUBSTITUTE(TRIM(D10:K10)," ",""))+1))}
A11: AQI | B11: AQI | C11: Good | D11: — (air clean and staying clean) | G11: Air clears to clean today — a good day for time outdoors. | H11: Air is clean this evening — enjoy the time out. | I11: Clean-air day — a simple evening cleanse is plenty before bed. | J11: Clean air all day — keep tonight simple: cleanse, then bed. | K11: Nothing clinging to skin today — one gentle wash and lights out. | L11: Clean-air days let skin's own antioxidant oils recover — no cleansing overload needed. (DYK #8) | M11: Keyed to FORECAST band | N11: {=IF(SUMPRODUCT(--ISNUMBER(SEARCH({"cover up","seek shade","reapply","sun protection","protection on","protect "},I11&" "&J11&" "&K11)))>0,"⚠ banned night verb","OK")} | O11: {=MAX(IF(LEN(TRIM(D11:K11))=0,0,LEN(TRIM(D11:K11))-LEN(SUBSTITUTE(TRIM(D11:K11)," ",""))+1))}
A12: AQI | B12: AQI | C12: Satisfactory | D12: — (only a small rise expected; deliberate exception — spec Rule R2 would fire on any band change) | G12: Air improves today — outdoor plans are back on. | H12: Air is fine for an evening outdoors. | I12: Mostly clean today — a gentle evening cleanse is enough. | J12: An easy air day — a light evening cleanse is all it takes. | K12: Air stayed kind — keep tonight to a quick, gentle cleanse. | L12: A small AQI rise barely moves skin load — why this row stays product-free. | M12: Keyed to FORECAST band · deliberate exception to Rule R2 | N12: {=IF(SUMPRODUCT(--ISNUMBER(SEARCH({"cover up","seek shade","reapply","sun protection","protection on","protect "},I12&" "&J12&" "&K12)))>0,"⚠ banned night verb","OK")} | O12: {=MAX(IF(LEN(TRIM(D12:K12))=0,0,LEN(TRIM(D12:K12))-LEN(SUBSTITUTE(TRIM(D12:K12)," ",""))+1))}
A13: AQI | B13: AQI | C13: Moderate | D13: Air worsens through the commute — plan to cleanse off grime later. | E13: Grime builds in the air today — a good cleanse tonight will matter. | H13: Evening air still carries grime — keep outdoor time easy. | I13: Cleanse off the day's settled grime tonight; moisturise after. | J13: The day's grime is sitting on your skin — wash it off before bed. | K13: A light film of city grime — one proper wash clears it. | L13: Polluted air halves skin's protective oils — the evening cleanse restores the reset. (DYK #8) | M13: Keyed to FORECAST band · CONTEXT: assumes weekday commute — use neutral fallback at weekends | N13: {=IF(SUMPRODUCT(--ISNUMBER(SEARCH({"cover up","seek shade","reapply","sun protection","protection on","protect "},I13&" "&J13&" "&K13)))>0,"⚠ banned night verb","OK")} | O13: {=MAX(IF(LEN(TRIM(D13:K13))=0,0,LEN(TRIM(D13:K13))-LEN(SUBSTITUTE(TRIM(D13:K13)," ",""))+1))}
A14: AQI | B14: AQI | C14: Poor | D14: Air gets worse through the day — cleanse well when you're back in. | E14: The air thickens as the day goes on — plan a proper cleanse later. | F14: Air slides two bands today — a good cleanse tonight is essential. | H14: Air stays poor into the evening — keep outdoor spells short. | I14: Wash off the day's pollution tonight and layer a little moisturiser. | J14: Pollution clung to you today — a good cleanse now, moisturiser after. | K14: Tonight's wash undoes the day's pollution — don't skip the moisturiser. | L14: Every +10 fine pollution particles raises pigment-spot scores ~9% — grime is a provable skin-ager. (DYK #14) | M14: Keyed to FORECAST band | N14: {=IF(SUMPRODUCT(--ISNUMBER(SEARCH({"cover up","seek shade","reapply","sun protection","protection on","protect "},I14&" "&J14&" "&K14)))>0,"⚠ banned night verb","OK")} | O14: {=MAX(IF(LEN(TRIM(D14:K14))=0,0,LEN(TRIM(D14:K14))-LEN(SUBSTITUTE(TRIM(D14:K14)," ",""))+1))}
A15: AQI | B15: AQI | C15: Very Poor | D15: Heavy pollution builds today — limit long outdoor spells and cleanse off later. | E15: A heavy-pollution day ahead — keep outdoor spells short and cleanse well after. | F15: Air quality collapses today — minimise time outside and cleanse well after. | H15: The evening smog-trapping weather keeps pollution high — better indoors tonight. | I15: Cleanse off the heavy grime tonight; moisturise to support the barrier. | J15: Heavy grime today — tonight's cleanse is the day's most useful step. | K15: Heavy air today — cleanse thoroughly, then feed the barrier. | L15: Pollution reaches skin from the surface and through blood — nightly cleanse plus antioxidants both help. (DYK #29) | M15: Keyed to FORECAST band | N15: {=IF(SUMPRODUCT(--ISNUMBER(SEARCH({"cover up","seek shade","reapply","sun protection","protection on","protect "},I15&" "&J15&" "&K15)))>0,"⚠ banned night verb","OK")} | O15: {=MAX(IF(LEN(TRIM(D15:K15))=0,0,LEN(TRIM(D15:K15))-LEN(SUBSTITUTE(TRIM(D15:K15)," ",""))+1))}
A16: AQI | B16: AQI | C16: Severe | D16: Hazardous air ahead — stay in where you can and cleanse off after any time out. | E16: The air turns hazardous today — indoors where possible; cleanse after any time out. | F16: A sharp crash to hazardous air today — stay in where you can; cleanse after any time out. | H16: Hazardous air into the night — stay in where you can. | I16: Wash the day's pollution off thoroughly tonight and moisturise well. | J16: The worst air does its damage overnight if it stays on — cleanse thoroughly. | K16: The grime is the day's real damage — a thorough wash, then rich support. | L16: Months in high pollution and skin makes less of its own moisturiser protein. (DYK #13) | M16: Keyed to FORECAST band | N16: {=IF(SUMPRODUCT(--ISNUMBER(SEARCH({"cover up","seek shade","reapply","sun protection","protection on","protect "},I16&" "&J16&" "&K16)))>0,"⚠ banned night verb","OK")} | O16: {=MAX(IF(LEN(TRIM(D16:K16))=0,0,LEN(TRIM(D16:K16))-LEN(SUBSTITUTE(TRIM(D16:K16)," ",""))+1))}
A17: Temperature | B17: Temperature | C17: Extreme Cold | D17: — (already extreme cold) | H17: Bitter cold deepens after sunset — layer up well if you step out. | I17: Bitter cold tonight — moisturise richly before bed to hold water in. | J17: Deep-freeze night — seal water in with a rich layer before bed. | K17: The coldest hours are ahead — the rich layer goes on before bed, not after. | L17: Cold nights spike water loss; skin loses most moisture in the coldest hours. (DYK #7) | M17: ⚠ Keyed to CURRENT band (inconsistent with UV/AQI rows) — engine must reconcile | N17: {=IF(SUMPRODUCT(--ISNUMBER(SEARCH({"cover up","seek shade","reapply","sun protection","protection on","protect "},I17&" "&J17&" "&K17)))>0,"⚠ banned night verb","OK")} | O17: {=MAX(IF(LEN(TRIM(D17:K17))=0,0,LEN(TRIM(D17:K17))-LEN(SUBSTITUTE(TRIM(D17:K17)," ",""))+1))}
A18: Temperature | B18: Temperature | C18: Cold | D18: It dips colder through the day — moisturise before you head out. | E18: A colder snap moves in today — moisturise before stepping out. | H18: The chill sharpens this evening — wrap up for time outside. | I18: Cold evening — a richer moisturiser before bed keeps skin from drying out. | J18: Cold nights pull water from skin — a richer layer before bed helps. | K18: Skin loses most water on cold nights — lock it in before sleep. | L18: Stepping from warm to cold air can spike water-loss six-fold. (DYK #7) | M18: ⚠ Keyed to CURRENT band (inconsistent with UV/AQI rows) — engine must reconcile | N18: {=IF(SUMPRODUCT(--ISNUMBER(SEARCH({"cover up","seek shade","reapply","sun protection","protection on","protect "},I18&" "&J18&" "&K18)))>0,"⚠ banned night verb","OK")} | O18: {=MAX(IF(LEN(TRIM(D18:K18))=0,0,LEN(TRIM(D18:K18))-LEN(SUBSTITUTE(TRIM(D18:K18)," ",""))+1))}
A19: Temperature | B19: Temperature | C19: Cool | D19: — (mild; usually no prep note) | G19: The cold lets up today — a milder day; ease back the heavy layering. | H19: A cool, easy evening — nothing extra needed. | I19: Cool evening — a light moisturiser before bed is enough. | J19: Cool night — a light moisturiser and you're done. | K19: An easy night — a light layer and you're done. | L19: Mild temperatures keep the barrier stable — no special step earns its place. | M19: ⚠ Keyed to CURRENT band (inconsistent with UV/AQI rows) — engine must reconcile | N19: {=IF(SUMPRODUCT(--ISNUMBER(SEARCH({"cover up","seek shade","reapply","sun protection","protection on","protect "},I19&" "&J19&" "&K19)))>0,"⚠ banned night verb","OK")} | O19: {=MAX(IF(LEN(TRIM(D19:K19))=0,0,LEN(TRIM(D19:K19))-LEN(SUBSTITUTE(TRIM(D19:K19)," ",""))+1))}
A20: Temperature | B20: Temperature | C20: Optimal | D20: A heatwave builds by afternoon — plan shade and water before it peaks. | E20: Heat builds to a peak this afternoon — shade and water will earn their keep. | F20: A rare jump straight into severe heat today — clear your midday plans; water and shade throughout. | G20: Temperature turns pleasant today — skin gets an easy day; enjoy it. | H20: A pleasant evening — enjoy it. | I20: An easy evening — keep up your usual routine. | J20: Nothing special needed tonight — your usual routine is right. | K20: Skin had a good day — just keep the routine steady. | L20: A comfortable day is a rare no-stress day for skin — keep it simple. | M20: ⚠ Keyed to CURRENT band (inconsistent with UV/AQI rows) — engine must reconcile | N20: {=IF(SUMPRODUCT(--ISNUMBER(SEARCH({"cover up","seek shade","reapply","sun protection","protection on","protect "},I20&" "&J20&" "&K20)))>0,"⚠ banned night verb","OK")} | O20: {=MAX(IF(LEN(TRIM(D20:K20))=0,0,LEN(TRIM(D20:K20))-LEN(SUBSTITUTE(TRIM(D20:K20)," ",""))+1))}
A21: Temperature | B21: Temperature | C21: Warm | D21: It heats up into the afternoon — plan a sweat rinse and stay shaded. | E21: The afternoon turns hot — a sweat rinse later will feel earned. | F21: Heat surges two bands today — treat midday like a heatwave: water, shade, cool rinses. | H21: Still warm out — water and light clothing if you're staying out. | I21: Warm evening — rinse off the day's sweat and keep moisturiser light. | J21: Warm night — rinse the day's sweat off and keep layers light. | K21: Sweat off, something light on — that's the whole night. | L21: Warm skin makes measurably more oil within an hour of the heat rising. (DYK #15) | M21: ⚠ Keyed to CURRENT band (inconsistent with UV/AQI rows) — engine must reconcile | N21: {=IF(SUMPRODUCT(--ISNUMBER(SEARCH({"cover up","seek shade","reapply","sun protection","protection on","protect "},I21&" "&J21&" "&K21)))>0,"⚠ banned night verb","OK")} | O21: {=MAX(IF(LEN(TRIM(D21:K21))=0,0,LEN(TRIM(D21:K21))-LEN(SUBSTITUTE(TRIM(D21:K21)," ",""))+1))}
A22: Temperature | B22: Temperature | C22: Hot | D22: It gets hotter by afternoon — plan water, shade and a sweat rinse. | E22: A hot afternoon ahead — line up water, shade and a rinse. | H22: Heat lingers into the evening — keep water handy if you're out. | I22: Heat easing tonight — rehydrate, rinse off sweat, moisturise lightly. | J22: The heat is finally easing — water, a rinse, and a light finish. | K22: Drink, rinse, keep it light — heat recovery in three steps. | L22: Heat plus sweat is prickly-heat territory — staying cool and rinsing settles it. (DYK #33) | M22: ⚠ Keyed to CURRENT band (inconsistent with UV/AQI rows) — engine must reconcile | N22: {=IF(SUMPRODUCT(--ISNUMBER(SEARCH({"cover up","seek shade","reapply","sun protection","protection on","protect "},I22&" "&J22&" "&K22)))>0,"⚠ banned night verb","OK")} | O22: {=MAX(IF(LEN(TRIM(D22:K22))=0,0,LEN(TRIM(D22:K22))-LEN(SUBSTITUTE(TRIM(D22:K22)," ",""))+1))}
A23: Temperature | B23: Temperature | C23: Extreme Heat | D23: A heatwave peaks today — plan water, shade and cool rinses before it does. | E23: Today peaks in a heatwave — get water, shade and cool rinses ready now. | H23: Still dangerously hot — stay shaded and keep drinking water. | I23: Peak heat easing — rehydrate well, rinse off sweat, keep moisturiser light. | J23: After a scorcher, rehydrate well — inside and out, kept light. | K23: Heatwave night — water first, a cool rinse, and the lightest finish. | L23: In a heatwave, rehydrating inside and out matters as much as anything topical. (DYK #15) | M23: ⚠ Keyed to CURRENT band (inconsistent with UV/AQI rows) — engine must reconcile | N23: {=IF(SUMPRODUCT(--ISNUMBER(SEARCH({"cover up","seek shade","reapply","sun protection","protection on","protect "},I23&" "&J23&" "&K23)))>0,"⚠ banned night verb","OK")} | O23: {=MAX(IF(LEN(TRIM(D23:K23))=0,0,LEN(TRIM(D23:K23))-LEN(SUBSTITUTE(TRIM(D23:K23)," ",""))+1))}
A24: Humidity | B24: Humidity | C24: Critical Low | D24: — (already bone-dry) | H24: Bone-dry evening air — skin may feel tight; a moisturiser helps. | I24: Bone-dry tonight — moisturise on slightly damp skin before bed. | J24: Desert-dry night — moisturise onto slightly damp skin and it holds. | K24: Bone-dry air works all night — give it a rich barrier to fight. | L24: Skin's natural moisturiser only forms well near 80–95% humidity — bone-dry air stalls it. (DYK #6) | M24: ⚠ Keyed to CURRENT band (inconsistent with UV/AQI rows) — engine must reconcile | N24: {=IF(SUMPRODUCT(--ISNUMBER(SEARCH({"cover up","seek shade","reapply","sun protection","protection on","protect "},I24&" "&J24&" "&K24)))>0,"⚠ banned night verb","OK")} | O24: {=MAX(IF(LEN(TRIM(D24:K24))=0,0,LEN(TRIM(D24:K24))-LEN(SUBSTITUTE(TRIM(D24:K24)," ",""))+1))}
A25: Humidity | B25: Humidity | C25: Very Low | D25: It dries out further today — carry a moisturiser to reapply. | E25: The air gets thirstier today — keep a moisturiser within reach. | H25: A dry evening — light moisturiser if skin starts to feel tight. | I25: Very dry evening — moisturise well before bed to hold water in. | J25: Very dry night air — a good layer before bed stops the tight-skin morning. | K25: Tight, flaky mornings start tonight — head them off with a good layer. | L25: Very dry air keeps pulling water out all night — a richer layer fights back. (DYK #6) | M25: ⚠ Keyed to CURRENT band (inconsistent with UV/AQI rows) — engine must reconcile | N25: {=IF(SUMPRODUCT(--ISNUMBER(SEARCH({"cover up","seek shade","reapply","sun protection","protection on","protect "},I25&" "&J25&" "&K25)))>0,"⚠ banned night verb","OK")} | O25: {=MAX(IF(LEN(TRIM(D25:K25))=0,0,LEN(TRIM(D25:K25))-LEN(SUBSTITUTE(TRIM(D25:K25)," ",""))+1))}
A26: Humidity | B26: Humidity | C26: Low | D26: Air dries out more today — moisturise after washing. | E26: Drier air moves in today — moisturise after every wash. | H26: Slightly dry evening air — nothing urgent. | I26: Drier evening — a moisturiser before bed keeps the barrier supported. | J26: Drier night — moisturiser before bed keeps the barrier topped up. | K26: A little extra moisturiser tonight saves dry patches tomorrow. | L26: Drier air slows the skin's moisture-making — topping up keeps the barrier even. (DYK #6) | M26: ⚠ Keyed to CURRENT band (inconsistent with UV/AQI rows) — engine must reconcile | N26: {=IF(SUMPRODUCT(--ISNUMBER(SEARCH({"cover up","seek shade","reapply","sun protection","protection on","protect "},I26&" "&J26&" "&K26)))>0,"⚠ banned night verb","OK")} | O26: {=MAX(IF(LEN(TRIM(D26:K26))=0,0,LEN(TRIM(D26:K26))-LEN(SUBSTITUTE(TRIM(D26:K26)," ",""))+1))}
A27: Humidity | B27: Humidity | C27: Optimal | D27: It turns humid later today — plan to keep skin and creases dry. | E27: Humidity climbs later — plan to keep skin and creases dry. | F27: Humidity surges from comfortable to soaking today — dry creases and a sweat rinse will matter. | G27: Humidity settles into the comfort zone today — skin can breathe easy. | H27: A comfortable evening — carry on as usual. | I27: An easy evening — keep up your usual routine. | J27: A kind night for skin — stick to your usual routine. | K27: Comfortable air, comfortable night — your usual routine is plenty. | L27: Comfortable humidity is where skin works best — nothing to correct. | M27: ⚠ Keyed to CURRENT band (inconsistent with UV/AQI rows) — engine must reconcile | N27: {=IF(SUMPRODUCT(--ISNUMBER(SEARCH({"cover up","seek shade","reapply","sun protection","protection on","protect "},I27&" "&J27&" "&K27)))>0,"⚠ banned night verb","OK")} | O27: {=MAX(IF(LEN(TRIM(D27:K27))=0,0,LEN(TRIM(D27:K27))-LEN(SUBSTITUTE(TRIM(D27:K27)," ",""))+1))}
A28: Humidity | B28: Humidity | C28: High | D28: It turns more humid today — plan a sweat rinse and keep skin creases dry. | E28: A muggier day ahead — a sweat rinse and dry creases will help. | F28: Humidity spikes to saturation today — cleanse often and keep creases dry. | H28: A sticky evening — light clothing helps sweat evaporate. | I28: Humid evening — a gentle cleanse clears sweat and oil before bed. | J28: Muggy night — a gentle cleanse clears the sweat film before bed. | K28: Sweat and oil built up today — clear them gently before sleep. | L28: Humid heat traps sweat in creases — prickly heat and irritation start there. (DYK #33) | M28: ⚠ Keyed to CURRENT band (inconsistent with UV/AQI rows) — engine must reconcile | N28: {=IF(SUMPRODUCT(--ISNUMBER(SEARCH({"cover up","seek shade","reapply","sun protection","protection on","protect "},I28&" "&J28&" "&K28)))>0,"⚠ banned night verb","OK")} | O28: {=MAX(IF(LEN(TRIM(D28:K28))=0,0,LEN(TRIM(D28:K28))-LEN(SUBSTITUTE(TRIM(D28:K28)," ",""))+1))}
A29: Humidity | B29: Humidity | C29: Very High | D29: Air saturates later today — plan to keep skin creases dry and cleanse off sweat. | E29: The air heads for saturation — keep creases dry and rinse off sweat. | H29: Humid evening — sweat sits on skin; take it easy out there. | I29: Still humid tonight — a gentle cleanse before bed; keep moisturiser light. | J29: Humidity hasn't let up — cleanse gently, moisturise sparingly. | K29: Still steamy — light cleanse, light moisturiser, nothing heavy. | L29: In sticky weather the scalp and creases stay damp for hours — a rinse keeps them fresh. (DYK #23) | M29: ⚠ Keyed to CURRENT band (inconsistent with UV/AQI rows) — engine must reconcile | N29: {=IF(SUMPRODUCT(--ISNUMBER(SEARCH({"cover up","seek shade","reapply","sun protection","protection on","protect "},I29&" "&J29&" "&K29)))>0,"⚠ banned night verb","OK")} | O29: {=MAX(IF(LEN(TRIM(D29:K29))=0,0,LEN(TRIM(D29:K29))-LEN(SUBSTITUTE(TRIM(D29:K29)," ",""))+1))}
A30: Humidity | B30: Humidity | C30: Extreme | D30: — (already saturated) | H30: Saturated evening air — keep time out light and easy. | I30: Saturated air tonight — cleanse off sweat, keep skin creases dry and moisturiser light. | J30: Saturated night — cleanse off sweat, dry the creases, keep it light. | K30: Air's fully saturated — cleanse, dry the creases, sleep light. | L30: Saturated air stops sweat evaporating — gentle, frequent cleansing beats heavy creams. (DYK #33) | M30: ⚠ Keyed to CURRENT band (inconsistent with UV/AQI rows) — engine must reconcile | N30: {=IF(SUMPRODUCT(--ISNUMBER(SEARCH({"cover up","seek shade","reapply","sun protection","protection on","protect "},I30&" "&J30&" "&K30)))>0,"⚠ banned night verb","OK")} | O30: {=MAX(IF(LEN(TRIM(D30:K30))=0,0,LEN(TRIM(D30:K30))-LEN(SUBSTITUTE(TRIM(D30:K30)," ",""))+1))}
A32: Compound-scenario overlays (21 named scenarios)
A33: Type | B33: Factor / Scenario | C33: Band / Key | D33: Morning add-on (use only if the band worsens today) | E33: Morning add-on — variant B (rotate with D) | F33: Morning add-on — big-jump variant (band worsens 2+ steps) | G33: Morning good-news note (use only if the band improves today) | H33: Early-evening action (~4–8pm) | I33: Night action (after ~8pm) | J33: Night action — variant B (rotate with I) | K33: Night action — variant C (rotate with I) | L33: Why it matters (micro-insight; DYK ref where noted) | M33: Keying & context flags | N33: QA: banned night verbs | O33: QA: max words (D:K)
A34: Compound | B34: Pre-Monsoon Sun & Heat | C34: C01 | D34: Strong sun and heat build by midday — put on sun protection and plan a sweat rinse before you go. | E34: Sun and heat gang up by midday — protection on and a rinse planned. | H34: Sun and heat are easing — keep protection on till sundown if you're still out. | I34: Sun and heat easing — rinse off sweat and sunscreen, then moisturise lightly. | J34: Sun and sweat both come off tonight — rinse well, then a light moisturiser. | K34: Today asked a lot of skin — sun and sweat off, a light drink on, sleep. | L34: Strong sun plus heat means more oil and more UV load at once — protect and rinse. (DYK #5, #15) | M34: Keyed to FORECAST band ("build today" phrasing) | N34: {=IF(SUMPRODUCT(--ISNUMBER(SEARCH({"cover up","seek shade","reapply","sun protection","protection on","protect "},I34&" "&J34&" "&K34)))>0,"⚠ banned night verb","OK")} | O34: {=MAX(IF(LEN(TRIM(D34:K34))=0,0,LEN(TRIM(D34:K34))-LEN(SUBSTITUTE(TRIM(D34:K34)," ",""))+1))}
A35: Compound | B35: Heatwave Crisis | C35: C02 | D35: A heatwave peaks today — water, shade and cool rinses before it does. | E35: Today is a heatwave day — stock water and plan cool rinses before the peak. | H35: Heat is still dangerous this evening — shade, water and minimal exertion. | I35: Peak heat easing — rehydrate well, rinse off sweat, keep moisturiser light overnight. | J35: After a scorching day, water first — then a rinse and the lightest layer. | K35: The heat did its worst; tonight is repair — water, rinse, light finish. | L35: Heatwave days need inside-out rehydration — topical care alone won't hold. (DYK #15) | M35: Keyed to FORECAST band | N35: {=IF(SUMPRODUCT(--ISNUMBER(SEARCH({"cover up","seek shade","reapply","sun protection","protection on","protect "},I35&" "&J35&" "&K35)))>0,"⚠ banned night verb","OK")} | O35: {=MAX(IF(LEN(TRIM(D35:K35))=0,0,LEN(TRIM(D35:K35))-LEN(SUBSTITUTE(TRIM(D35:K35)," ",""))+1))}
A36: Compound | B36: Dry-Heat Desert Day | C36: C03 | D36: Dry heat and strong sun build today — moisturise and put on sun protection before heading out. | E36: Desert-dry heat and strong sun today — moisturise, then protect before out. | H36: The heat fades but the dryness stays — moisturiser if skin feels tight. | I36: Dry, hot day done — moisturise on damp skin and cleanse off sunscreen. | J36: Wash off the sunscreen, then moisturise damp skin to win back lost water. | K36: Desert day done — damp-skin moisturising beats dry-skin moisturising tonight. | L36: Dry heat plus sun stalls moisture-making while UV bites — moisturise, then protect. (DYK #6) | M36: Keyed to FORECAST band | N36: {=IF(SUMPRODUCT(--ISNUMBER(SEARCH({"cover up","seek shade","reapply","sun protection","protection on","protect "},I36&" "&J36&" "&K36)))>0,"⚠ banned night verb","OK")} | O36: {=MAX(IF(LEN(TRIM(D36:K36))=0,0,LEN(TRIM(D36:K36))-LEN(SUBSTITUTE(TRIM(D36:K36)," ",""))+1))}
A37: Compound | B37: Beach Day UV | C37: C04 | D37: Glare-boosted UV peaks midday — sun protection, shade and cover-ups before you're out. | E37: Water and sand bounce extra UV today — protect and plan shade before you go. | H37: Late-beach glare still burns — keep protection on till the sun is down. | I37: Beach day over — cleanse off salt, sand and sunscreen; rehydrate skin. | J37: Salt, sand and sunscreen all come off tonight — then let skin drink. | K37: Beach glow now, beach residue later — wash it all off before bed. | L37: Water and sand bounce 25–50% extra UV up at you — glare burns from below too. (DYK #2) | M37: Keyed to FORECAST band · CONTEXT: assumes beach/waterside outing | N37: {=IF(SUMPRODUCT(--ISNUMBER(SEARCH({"cover up","seek shade","reapply","sun protection","protection on","protect "},I37&" "&J37&" "&K37)))>0,"⚠ banned night verb","OK")} | O37: {=MAX(IF(LEN(TRIM(D37:K37))=0,0,LEN(TRIM(D37:K37))-LEN(SUBSTITUTE(TRIM(D37:K37)," ",""))+1))}
A38: Compound | B38: Hot-Humid Coastal Summer | C38: C05 | D38: Heat and humidity build today — plan a sweat rinse and keep skin creases dry. | E38: A hot, sticky one today — plan a rinse and keep creases dry. | H38: A sticky evening — light clothes and an easy pace. | I38: Sticky day easing — a gentle cleanse clears sweat and oil before bed. | J38: A day of sweat needs a gentle wash tonight — keep the finish light. | K38: Sticky day, simple night: gentle wash, light layer, dry creases. | L38: Humid heat traps sweat in creases — the classic prickly-heat setup. (DYK #33) | M38: Keyed to FORECAST band | N38: {=IF(SUMPRODUCT(--ISNUMBER(SEARCH({"cover up","seek shade","reapply","sun protection","protection on","protect "},I38&" "&J38&" "&K38)))>0,"⚠ banned night verb","OK")} | O38: {=MAX(IF(LEN(TRIM(D38:K38))=0,0,LEN(TRIM(D38:K38))-LEN(SUBSTITUTE(TRIM(D38:K38)," ",""))+1))}
A39: Compound | B39: Monsoon Acne Trifecta | C39: C06 | D39: Humid, polluted heat builds today — plan to keep skin dry and cleanse off sweat and grime. | E39: Heat, humidity and grime all day — tonight's cleanse will matter. | H39: Humid, grimy evening air — keep outdoor time easy. | I39: Cleanse off the day's sweat and grime tonight; keep moisturiser light and skin dry. | J39: Sweat and grime clog overnight if they stay — cleanse gently, finish light and dry. | K39: Breakout weather peaks overnight if grime stays — cleanse gently before bed. | L39: Humidity plus pollution: grime sticks to damp skin — the nightly cleanse earns its keep. (DYK #29) | M39: Keyed to FORECAST band | N39: {=IF(SUMPRODUCT(--ISNUMBER(SEARCH({"cover up","seek shade","reapply","sun protection","protection on","protect "},I39&" "&J39&" "&K39)))>0,"⚠ banned night verb","OK")} | O39: {=MAX(IF(LEN(TRIM(D39:K39))=0,0,LEN(TRIM(D39:K39))-LEN(SUBSTITUTE(TRIM(D39:K39)," ",""))+1))}
A40: Compound | B40: Coastal Monsoon Standard | C40: C07 | D40: Humid air holds all day — plan a sweat rinse to keep skin fresh. | E40: Humid air parks over the day — a sweat rinse keeps skin fresh. | H40: A humid evening — take it easy; cleanse when you're back in. | I40: Humid day done — a gentle cleanse before bed clears sweat and oil. | J40: Rinse the muggy day away — light cleanse, light layer, done. | K40: Muggy day over — one gentle wash keeps pores clear tonight. | L40: Damp skin all day invites irritation — a sweat rinse keeps it fresh. (DYK #23) | M40: Keyed to FORECAST band | N40: {=IF(SUMPRODUCT(--ISNUMBER(SEARCH({"cover up","seek shade","reapply","sun protection","protection on","protect "},I40&" "&J40&" "&K40)))>0,"⚠ banned night verb","OK")} | O40: {=MAX(IF(LEN(TRIM(D40:K40))=0,0,LEN(TRIM(D40:K40))-LEN(SUBSTITUTE(TRIM(D40:K40)," ",""))+1))}
A41: Compound | B41: Tropical NE Saturated | C41: C08 | D41: Saturated air all day — plan to keep skin creases dry and cleanse often. | E41: Saturation all day — dry creases and frequent cleansing win today. | H41: Air stays saturated this evening — keep exertion light. | I41: Still saturated tonight — cleanse off sweat and keep skin creases dry before bed. | J41: Before bed: sweat off, creases dry, moisturiser minimal. | K41: Saturation day: the win is dry creases and a feather-light finish. | L41: Saturated air stops sweat drying — frequent gentle cleansing wins. (DYK #33) | M41: Keyed to FORECAST band | N41: {=IF(SUMPRODUCT(--ISNUMBER(SEARCH({"cover up","seek shade","reapply","sun protection","protection on","protect "},I41&" "&J41&" "&K41)))>0,"⚠ banned night verb","OK")} | O41: {=MAX(IF(LEN(TRIM(D41:K41))=0,0,LEN(TRIM(D41:K41))-LEN(SUBSTITUTE(TRIM(D41:K41)," ",""))+1))}
A42: Compound | B42: Pre-Monsoon Humidity Surge | C42: C09 | D42: Humid heat and strong sun build today — sweat rinse, light moisturiser and sun protection planned. | E42: Humid heat plus strong sun today — rinse, light moisturiser, protection. | H42: Humid heat lingers — water and shade if you're still out. | I42: Humid heat easing — cleanse off sweat and sunscreen, keep moisturiser light. | J42: Sweat and sunscreen come off together tonight — keep what follows light. | K42: Three stressors today — one calm night: rinse, dry, light layer. | L42: Heat, humidity and sun stack every stressor — rinse, light moisturiser, protection. (DYK #15) | M42: Keyed to FORECAST band | N42: {=IF(SUMPRODUCT(--ISNUMBER(SEARCH({"cover up","seek shade","reapply","sun protection","protection on","protect "},I42&" "&J42&" "&K42)))>0,"⚠ banned night verb","OK")} | O42: {=MAX(IF(LEN(TRIM(D42:K42))=0,0,LEN(TRIM(D42:K42))-LEN(SUBSTITUTE(TRIM(D42:K42)," ",""))+1))}
...

Sheet Gap Analysis
A1: Gap Analysis — Evidence Base coverage vs Scenario Library v3.5
A2: Every concern in the Evidence Base Coverage_Matrix, checked against what the Scenario Library now builds. STATUS: ✓ in v3.5 = scenario cells exist · NEW in v3.5 = added this release · Modifier/Education = supported as a nudge, not weather cells · Roadmap = evidence too thin or non-environmental.
A4: Concern (Evidence Base) | B4: Total cited rows | C4: India-relevant | D4: Top factor sheets | E4: In Scenario Library? | F4: How it's covered | G4: Best confidence achievable | H4: Notes / what's still missing
A5: barrier | B5: 501 | C5: 312 | D5: Humidity(151), Pollution(101), Lifestyle(97) | E5: ✓ in v3.5 | F5: Underlies Dryness + Eczema cells across all 4 factors | G5: HIGH | H5: Fully covered as the core of the library.
A6: sensitivity | B6: 471 | C6: 338 | D6: Lifestyle(124), UV(111), Humidity(91) | E6: ✓ in v3.5 | F6: Sensitive skin type runs through every cell + Stress/Sleep modifiers | G6: HIGH | H6: Covered as a skin-type lens on all concerns.
A7: pigmentation | B7: 425 | C7: 326 | D7: UV(232), Lifestyle(62), Nutrition(59) | E7: ✓ in v3.5 | F7: Uneven Skin Tone / Tan + Melasma cells | G7: HIGH | H7: Fully covered.
A8: uv_sun_protection | B8: 386 | C8: 275 | D8: UV(294), Pollution(33), Lifestyle(25) | E8: ✓ in v3.5 | F8: Whole UV factor + Premature Aging cells | G8: HIGH | H8: Fully covered.
A9: nutritional | B9: 327 | C9: 237 | D9: UV(119), Nutrition(115), Lifestyle(31) | E9: ✓ in v3.5 | F9: Nutrition Modifiers sheet (7 nudges) | G9: MODERATE | H9: Covered as personalisation nudges, not weather cells (correct — diet isn't an environmental trigger).
A10: acne | B10: 288 | C10: 224 | D10: Lifestyle(91), UV(80), Temperature(39) | E10: ✓ in v3.5 | F10: Acne cells across all 4 factors | G10: HIGH | H10: Fully covered.
A11: aging | B11: 242 | C11: 120 | D11: UV(92), Nutrition(76), Pollution(26) | E11: ✓ in v3.5 | F11: Premature Aging / Sun Damage cells (UV, AQI, Temp) | G11: HIGH | H11: Added in v3.4; retained.
A12: eczema | B12: 226 | C12: 150 | D12: Humidity(63), Lifestyle(56), Nutrition(30) | E12: ✓ in v3.5 | F12: Eczema cells across all 4 factors | G12: HIGH | H12: Fully covered.
A13: melasma | B13: 163 | C13: 102 | D13: UV(96), Nutrition(29), Lifestyle(21) | E13: ✓ in v3.5 | F13: Melasma cells across all 4 factors | G13: MODERATE | H13: Fully covered.
A14: pollution_specific | B14: 153 | C14: 106 | D14: Pollution(100), UV(27), Lifestyle(10) | E14: ✓ in v3.5 | F14: Whole AQI factor | G14: HIGH | H14: Fully covered.
A15: hair_loss | B15: 109 | C15: 90 | D15: Lifestyle(63), UV(11), Humidity(11) | E15: NEW in v3.5 | F15: Hair & Scalp (Shedding): 90 single-factor + 85 compound cells | G15: MODERATE | H15: Environmental triggers (scalp UV, grime, sweat) covered across single-factor AND named scenarios. Hormonal/genetic hair loss stays a dermatologist topic.
A16: fungal_infections | B16: 80 | C16: 76 | D16: Humidity(51), Temperature(14), Pollution(7) | E16: ✓ in v3.5 | F16: Fungal Infection (Sweat & Folds) cells (Humidity, Temp) | G16: HIGH | H16: Added in v3.4; retained.
... A22: miliaria_heat | B22: 12 | C22: 12 | D22: Humidity(8), Temperature(4) | E22: ✓ in v3.5 | F22: Heat Rash (Prickly Heat) cells (Temp, Humidity) | G22: MODERATE | H22: Added in v3.4; retained.

Sheet 4. Temperature Cells
A1: Scenario ID | B1: Band | C1: Range | D1: Skin Type | E1: Concern | F1: Risk | G1: Risk Level | H1: Confidence | I1: Evidence Summary | J1: PMID Anchors | K1: L0 Compact (≤20w) | L1: L1 Personalised (≤40w) | M1: L2 Explainer (60–90w) | N1: Action Cluster | O1: Applicable Zones | P1: Indian Cities/Season
A2: T-EXTR-NOR-DRYN-001 | B2: Extreme Cold | C2: <5°C | D2: Normal | E2: Dryness | F2: 5 | G2: Critical | H2: HIGH | I2: 39 cites · 26 PMID · 8 book · 7 India-relevant | J2: PMID:37953512 | PMID:35053992 | PMID:31029804 | K2: Sub-zero air holds almost no moisture. Lock in moisture to protect your skin now. | L2: Sub-zero air holds almost no moisture. For your skin with dryness, this is as tough as it gets for your skin. Layer a water-binding humectant (like glycerin) on damp skin, then seal with an emollient. Apply within three minutes of any wash. | M2: Sub-zero air holds almost no moisture. Air this cold holds almost no water — your skin is losing moisture every second it's exposed. In Indian context: the Himalayan belt (Dec–Jan); -ve impact in mountain belt. Build moisture from the inside out: water-binding humectants (like glycerin) on damp skin, sealed with an emollient layer that locks moisture in. Apply within three minutes of any wash before water evaporates. A bedroom humidifier helps overnight. | N2: Hydrate | O2: CH | P2: Kashmir, Himachal (Dec–Jan); -ve impact in mountain belt
